Workbook

Sheet Planning Phase
B7: Risk | D7: Initial Risk | G7: Proposed Control Measures | I7: Revised Risk | L7: Selected | M7: Actions | P7: Initial Scores | U7: Initial Scores
B8: Source | C8: Event | D8: Likelihood | E8: Consequence | F8: Rating | G8: Options | H8: Considerations | I8: Likelihood | J8: Consequence | K8: Rating | M8: Who | N8: What | P8: L | Q8: C | U8: L | V8: C
B9: Vulnerable Road Users - pedestrians, cyclists, people with disabilities and wheeled path users | S9: Very High
B10: Works impact on existing path routes resulting in VRU unable to pass the site safely using existing paths | C10: VRUs cross roads in an unsafe manner at unsigned locations | F10: =IF(P10*Q10=0,$S$14,VLOOKUP(Q10,Lookups!$D$4:$J$8,'Planning Phase'!P10+2)) -> Select L & C | K10: =IF(U10*V10=0,$S$14,VLOOKUP(V10,Lookups!$D$4:$J$8,'Planning Phase'!U10+2)) -> Select L & C | P10: =IF(D10=Lookups!$B$4,1,IF(D10=Lookups!$B$5,2,IF(D10=Lookups!$B$6,3,IF(D10=Lookups!$B$7,4,IF(D10=Lookups!$B$8,5,0))))) -> 0 | Q10: =IF(E10=Lookups!$C$4,1,IF(E10=Lookups!$C$5,2,IF(E10=Lookups!$C$6,3,IF(E10=Lookups!$C$7,4,IF(E10=Lookups!$C$8,5,0))))) -> 0 | S10: High | U10: =IF(I10=Lookups!$B$4,1,IF(I10=Lookups!$B$5,2,IF(I10=Lookups!$B$6,3,IF(I10=Lookups!$B$7,4,IF(I10=Lookups!$B$8,5,0))))) -> 0 | V10: =IF(J10=Lookups!$C$4,1,IF(J10=Lookups!$C$5,2,IF(J10=Lookups!$C$6,3,IF(J10=Lookups!$C$7,4,IF(J10=Lookups!$C$8,5,0))))) -> 0
C11: VRUs use a temporary path route which has a surface not appropriate for wheeled path users, visually impaired and VRU with mobility issues. Results in trip or fall hazards | F11: =IF(P11*Q11=0,$S$14,VLOOKUP(Q11,Lookups!$D$4:$J$8,'Planning Phase'!P11+2)) -> Select L & C | K11: =IF(U11*V11=0,$S$14,VLOOKUP(V11,Lookups!$D$4:$J$8,'Planning Phase'!U11+2)) -> Select L & C | P11: =IF(D11=Lookups!$B$4,1,IF(D11=Lookups!$B$5,2,IF(D11=Lookups!$B$6,3,IF(D11=Lookups!$B$7,4,IF(D11=Lookups!$B$8,5,0))))) -> 0 | Q11: =IF(E11=Lookups!$C$4,1,IF(E11=Lookups!$C$5,2,IF(E11=Lookups!$C$6,3,IF(E11=Lookups!$C$7,4,IF(E11=Lookups!$C$8,5,0))))) -> 0 | S11: Medium | U11: =IF(I11=Lookups!$B$4,1,IF(I11=Lookups!$B$5,2,IF(I11=Lookups!$B$6,3,IF(I11=Lookups!$B$7,4,IF(I11=Lookups!$B$8,5,0))))) -> 0 | V11: =IF(J11=Lookups!$C$4,1,IF(J11=Lookups!$C$5,2,IF(J11=Lookups!$C$6,3,IF(J11=Lookups!$C$7,4,IF(J11=Lookups!$C$8,5,0))))) -> 0
C12: VRUs diverted to a detour route which is an unacceptable length with a lower likelihood of VRUs using the defined route | F12: =IF(P12*Q12=0,$S$14,VLOOKUP(Q12,Lookups!$D$4:$J$8,'Planning Phase'!P12+2)) -> Select L & C | K12: =IF(U12*V12=0,$S$14,VLOOKUP(V12,Lookups!$D$4:$J$8,'Planning Phase'!U12+2)) -> Select L & C | P12: =IF(D12=Lookups!$B$4,1,IF(D12=Lookups!$B$5,2,IF(D12=Lookups!$B$6,3,IF(D12=Lookups!$B$7,4,IF(D12=Lookups!$B$8,5,0))))) -> 0 | Q12: =IF(E12=Lookups!$C$4,1,IF(E12=Lookups!$C$5,2,IF(E12=Lookups!$C$6,3,IF(E12=Lookups!$C$7,4,IF(E12=Lookups!$C$8,5,0))))) -> 0 | S12: Low | U12: =IF(I12=Lookups!$B$4,1,IF(I12=Lookups!$B$5,2,IF(I12=Lookups!$B$6,3,IF(I12=Lookups!$B$7,4,IF(I12=Lookups!$B$8,5,0))))) -> 0 | V12: =IF(J12=Lookups!$C$4,1,IF(J12=Lookups!$C$5,2,IF(J12=Lookups!$C$6,3,IF(J12=Lookups!$C$7,4,IF(J12=Lookups!$C$8,5,0))))) -> 0
C13: VRUs following unfamiliar and illegible paths due to lack of clear direction interact with work site vehicles, equipment or other vehicles moving through the site. | F13: =IF(P13*Q13=0,$S$14,VLOOKUP(Q13,Lookups!$D$4:$J$8,'Planning Phase'!P13+2)) -> Select L & C | K13: =IF(U13*V13=0,$S$14,VLOOKUP(V13,Lookups!$D$4:$J$8,'Planning Phase'!U13+2)) -> Select L & C | P13: =IF(D13=Lookups!$B$4,1,IF(D13=Lookups!$B$5,2,IF(D13=Lookups!$B$6,3,IF(D13=Lookups!$B$7,4,IF(D13=Lookups!$B$8,5,0))))) -> 0 | Q13: =IF(E13=Lookups!$C$4,1,IF(E13=Lookups!$C$5,2,IF(E13=Lookups!$C$6,3,IF(E13=Lookups!$C$7,4,IF(E13=Lookups!$C$8,5,0))))) -> 0 | S13: Negligible | U13: =IF(I13=Lookups!$B$4,1,IF(I13=Lookups!$B$5,2,IF(I13=Lookups!$B$6,3,IF(I13=Lookups!$B$7,4,IF(I13=Lookups!$B$8,5,0))))) -> 0 | V13: =IF(J13=Lookups!$C$4,1,IF(J13=Lookups!$C$5,2,IF(J13=Lookups!$C$6,3,IF(J13=Lookups!$C$7,4,IF(J13=Lookups!$C$8,5,0))))) -> 0
C14: VRUs confused by TTM layout and follow incorrect route into site | F14: =IF(P14*Q14=0,$S$14,VLOOKUP(Q14,Lookups!$D$4:$J$8,'Planning Phase'!P14+2)) -> Select L & C | K14: =IF(U14*V14=0,$S$14,VLOOKUP(V14,Lookups!$D$4:$J$8,'Planning Phase'!U14+2)) -> Select L & C | P14: =IF(D14=Lookups!$B$4,1,IF(D14=Lookups!$B$5,2,IF(D14=Lookups!$B$6,3,IF(D14=Lookups!$B$7,4,IF(D14=Lookups!$B$8,5,0))))) -> 0 | Q14: =IF(E14=Lookups!$C$4,1,IF(E14=Lookups!$C$5,2,IF(E14=Lookups!$C$6,3,IF(E14=Lookups!$C$7,4,IF(E14=Lookups!$C$8,5,0))))) -> 0 | S14: =IF(AC14*AD14=0,"Select L & C",VLOOKUP(AD14,Lookups!Q8:W12,'Planning Phase'!AC14+2)) -> Select L & C | U14: =IF(I14=Lookups!$B$4,1,IF(I14=Lookups!$B$5,2,IF(I14=Lookups!$B$6,3,IF(I14=Lookups!$B$7,4,IF(I14=Lookups!$B$8,5,0))))) -> 0 | V14: =IF(J14=Lookups!$C$4,1,IF(J14=Lookups!$C$5,2,IF(J14=Lookups!$C$6,3,IF(J14=Lookups!$C$7,4,IF(J14=Lookups!$C$8,5,0))))) -> 0
C15: VRUs entering live traffic lanes in unsafe locations | F15: =IF(P15*Q15=0,$S$14,VLOOKUP(Q15,Lookups!$D$4:$J$8,'Planning Phase'!P15+2)) -> Select L & C | K15: =IF(U15*V15=0,$S$14,VLOOKUP(V15,Lookups!$D$4:$J$8,'Planning Phase'!U15+2)) -> Select L & C | P15: =IF(D15=Lookups!$B$4,1,IF(D15=Lookups!$B$5,2,IF(D15=Lookups!$B$6,3,IF(D15=Lookups!$B$7,4,IF(D15=Lookups!$B$8,5,0))))) -> 0 | Q15: =IF(E15=Lookups!$C$4,1,IF(E15=Lookups!$C$5,2,IF(E15=Lookups!$C$6,3,IF(E15=Lookups!$C$7,4,IF(E15=Lookups!$C$8,5,0))))) -> 0 | U15: =IF(I15=Lookups!$B$4,1,IF(I15=Lookups!$B$5,2,IF(I15=Lookups!$B$6,3,IF(I15=Lookups!$B$7,4,IF(I15=Lookups!$B$8,5,0))))) -> 0 | V15: =IF(J15=Lookups!$C$4,1,IF(J15=Lookups!$C$5,2,IF(J15=Lookups!$C$6,3,IF(J15=Lookups!$C$7,4,IF(J15=Lookups!$C$8,5,0))))) -> 0
C16: VRUs confused by TTM layout or path direction is not clear - and follow unsafe route around site | F16: =IF(P16*Q16=0,$S$14,VLOOKUP(Q16,Lookups!$D$4:$J$8,'Planning Phase'!P16+2)) -> Select L & C | K16: =IF(U16*V16=0,$S$14,VLOOKUP(V16,Lookups!$D$4:$J$8,'Planning Phase'!U16+2)) -> Select L & C | P16: =IF(D16=Lookups!$B$4,1,IF(D16=Lookups!$B$5,2,IF(D16=Lookups!$B$6,3,IF(D16=Lookups!$B$7,4,IF(D16=Lookups!$B$8,5,0))))) -> 0 | Q16: =IF(E16=Lookups!$C$4,1,IF(E16=Lookups!$C$5,2,IF(E16=Lookups!$C$6,3,IF(E16=Lookups!$C$7,4,IF(E16=Lookups!$C$8,5,0))))) -> 0 | U16: =IF(I16=Lookups!$B$4,1,IF(I16=Lookups!$B$5,2,IF(I16=Lookups!$B$6,3,IF(I16=Lookups!$B$7,4,IF(I16=Lookups!$B$8,5,0))))) -> 0 | V16: =IF(J16=Lookups!$C$4,1,IF(J16=Lookups!$C$5,2,IF(J16=Lookups!$C$6,3,IF(J16=Lookups!$C$7,4,IF(J16=Lookups!$C$8,5,0))))) -> 0
B17: Works impact on existing crossings resulting in VRU unable to use the existing crossing route | C17: Altered crossing is not clear to path users leading to unpredictable pedestrian behaviour when crossing roads | F17: =IF(P17*Q17=0,$S$14,VLOOKUP(Q17,Lookups!$D$4:$J$8,'Planning Phase'!P17+2)) -> Select L & C | K17: =IF(U17*V17=0,$S$14,VLOOKUP(V17,Lookups!$D$4:$J$8,'Planning Phase'!U17+2)) -> Select L & C | P17: =IF(D17=Lookups!$B$4,1,IF(D17=Lookups!$B$5,2,IF(D17=Lookups!$B$6,3,IF(D17=Lookups!$B$7,4,IF(D17=Lookups!$B$8,5,0))))) -> 0 | Q17: =IF(E17=Lookups!$C$4,1,IF(E17=Lookups!$C$5,2,IF(E17=Lookups!$C$6,3,IF(E17=Lookups!$C$7,4,IF(E17=Lookups!$C$8,5,0))))) -> 0 | U17: =IF(I17=Lookups!$B$4,1,IF(I17=Lookups!$B$5,2,IF(I17=Lookups!$B$6,3,IF(I17=Lookups!$B$7,4,IF(I17=Lookups!$B$8,5,0))))) -> 0 | V17: =IF(J17=Lookups!$C$4,1,IF(J17=Lookups!$C$5,2,IF(J17=Lookups!$C$6,3,IF(J17=Lookups!$C$7,4,IF(J17=Lookups!$C$8,5,0))))) -> 0
C18: Safe school crossing practices compromised resulting in children crossing the road in an an unsafe and unpredictable manner in and around the site | F18: =IF(P18*Q18=0,$S$14,VLOOKUP(Q18,Lookups!$D$4:$J$8,'Planning Phase'!P18+2)) -> Select L & C | K18: =IF(U18*V18=0,$S$14,VLOOKUP(V18,Lookups!$D$4:$J$8,'Planning Phase'!U18+2)) -> Select L & C | P18: =IF(D18=Lookups!$B$4,1,IF(D18=Lookups!$B$5,2,IF(D18=Lookups!$B$6,3,IF(D18=Lookups!$B$7,4,IF(D18=Lookups!$B$8,5,0))))) -> 0 | Q18: =IF(E18=Lookups!$C$4,1,IF(E18=Lookups!$C$5,2,IF(E18=Lookups!$C$6,3,IF(E18=Lookups!$C$7,4,IF(E18=Lookups!$C$8,5,0))))) -> 0 | U18: =IF(I18=Lookups!$B$4,1,IF(I18=Lookups!$B$5,2,IF(I18=Lookups!$B$6,3,IF(I18=Lookups!$B$7,4,IF(I18=Lookups!$B$8,5,0))))) -> 0 | V18: =IF(J18=Lookups!$C$4,1,IF(J18=Lookups!$C$5,2,IF(J18=Lookups!$C$6,3,IF(J18=Lookups!$C$7,4,IF(J18=Lookups!$C$8,5,0))))) -> 0
B19: Schools, clubs or other facilities that may generate high volumes of pedestrian or cycle traffic | C19: Temporary or impacted path route has inadequate capacity leading to VRUs crossing at unsafe locations or travelling along the road leading to conflicts between path users and traffic, or to conflicts between VRUs and worksite hazards, plant movements or unsuitable routes | F19: =IF(P19*Q19=0,$S$14,VLOOKUP(Q19,Lookups!$D$4:$J$8,'Planning Phase'!P19+2)) -> Select L & C | K19: =IF(U19*V19=0,$S$14,VLOOKUP(V19,Lookups!$D$4:$J$8,'Planning Phase'!U19+2)) -> Select L & C | P19: =IF(D19=Lookups!$B$4,1,IF(D19=Lookups!$B$5,2,IF(D19=Lookups!$B$6,3,IF(D19=Lookups!$B$7,4,IF(D19=Lookups!$B$8,5,0))))) -> 0 | Q19: =IF(E19=Lookups!$C$4,1,IF(E19=Lookups!$C$5,2,IF(E19=Lookups!$C$6,3,IF(E19=Lookups!$C$7,4,IF(E19=Lookups!$C$8,5,0))))) -> 0 | U19: =IF(I19=Lookups!$B$4,1,IF(I19=Lookups!$B$5,2,IF(I19=Lookups!$B$6,3,IF(I19=Lookups!$B$7,4,IF(I19=Lookups!$B$8,5,0))))) -> 0 | V19: =IF(J19=Lookups!$C$4,1,IF(J19=Lookups!$C$5,2,IF(J19=Lookups!$C$6,3,IF(J19=Lookups!$C$7,4,IF(J19=Lookups!$C$8,5,0))))) -> 0
B20: Facilities such as hotels or taverns where pedestrians may have their judgement impaired | C20: VRUs may be confused by temporary alternative routes and enter the worksite of live traffic lanes at unsafe locations | F20: =IF(P20*Q20=0,$S$14,VLOOKUP(Q20,Lookups!$D$4:$J$8,'Planning Phase'!P20+2)) -> Select L & C | K20: =IF(U20*V20=0,$S$14,VLOOKUP(V20,Lookups!$D$4:$J$8,'Planning Phase'!U20+2)) -> Select L & C
B21: High cycle volumes on road or in defined bicycle lane / shoulder which is impacted by works | C21: Cyclist transition to footpath does not occur at a safe location leading to possible cyclist injury or conflict with other path users | F21: =IF(P21*Q21=0,$S$14,VLOOKUP(Q21,Lookups!$D$4:$J$8,'Planning Phase'!P21+2)) -> Select L & C | K21: =IF(U21*V21=0,$S$14,VLOOKUP(V21,Lookups!$D$4:$J$8,'Planning Phase'!U21+2)) -> Select L & C
C22: Cyclist merge with general traffic lanes at unsafe location or in unsafe manner leading to collision with other road vehicles. | F22: =IF(P22*Q22=0,$S$14,VLOOKUP(Q22,Lookups!$D$4:$J$8,'Planning Phase'!P22+2)) -> Select L & C | K22: =IF(U22*V22=0,$S$14,VLOOKUP(V22,Lookups!$D$4:$J$8,'Planning Phase'!U22+2)) -> Select L & C | P22: =IF(D22=Lookups!$B$4,1,IF(D22=Lookups!$B$5,2,IF(D22=Lookups!$B$6,3,IF(D22=Lookups!$B$7,4,IF(D22=Lookups!$B$8,5,0))))) -> 0 | Q22: =IF(E22=Lookups!$C$4,1,IF(E22=Lookups!$C$5,2,IF(E22=Lookups!$C$6,3,IF(E22=Lookups!$C$7,4,IF(E22=Lookups!$C$8,5,0))))) -> 0 | U22: =IF(I22=Lookups!$B$4,1,IF(I22=Lookups!$B$5,2,IF(I22=Lookups!$B$6,3,IF(I22=Lookups!$B$7,4,IF(I22=Lookups!$B$8,5,0))))) -> 0 | V22: =IF(J22=Lookups!$C$4,1,IF(J22=Lookups!$C$5,2,IF(J22=Lookups!$C$6,3,IF(J22=Lookups!$C$7,4,IF(J22=Lookups!$C$8,5,0))))) -> 0
B23: Traffic Impacts | P23: =IF(D23=Lookups!$B$4,1,IF(D23=Lookups!$B$5,2,IF(D23=Lookups!$B$6,3,IF(D23=Lookups!$B$7,4,IF(D23=Lookups!$B$8,5,0))))) -> 0 | Q23: =IF(E23=Lookups!$C$4,1,IF(E23=Lookups!$C$5,2,IF(E23=Lookups!$C$6,3,IF(E23=Lookups!$C$7,4,IF(E23=Lookups!$C$8,5,0))))) -> 0 | U23: =IF(I23=Lookups!$B$4,1,IF(I23=Lookups!$B$5,2,IF(I23=Lookups!$B$6,3,IF(I23=Lookups!$B$7,4,IF(I23=Lookups!$B$8,5,0))))) -> 0 | V23: =IF(J23=Lookups!$C$4,1,IF(J23=Lookups!$C$5,2,IF(J23=Lookups!$C$6,3,IF(J23=Lookups!$C$7,4,IF(J23=Lookups!$C$8,5,0))))) -> 0
B24: Excessive length of worksite, including rural areas | C24: Dangerous / agressive driver behaviour resulting from excessive length of queues because of time needed to manage reversible flow leading to lack of community / road user acceptance of the worksite | F24: =IF(P24*Q24=0,$S$14,VLOOKUP(Q24,Lookups!$D$4:$J$8,'Planning Phase'!P24+2)) -> Select L & C | K24: =IF(U24*V24=0,$S$14,VLOOKUP(V24,Lookups!$D$4:$J$8,'Planning Phase'!U24+2)) -> Select L & C | P24: =IF(D24=Lookups!$B$4,1,IF(D24=Lookups!$B$5,2,IF(D24=Lookups!$B$6,3,IF(D24=Lookups!$B$7,4,IF(D24=Lookups!$B$8,5,0))))) -> 0 | Q24: =IF(E24=Lookups!$C$4,1,IF(E24=Lookups!$C$5,2,IF(E24=Lookups!$C$6,3,IF(E24=Lookups!$C$7,4,IF(E24=Lookups!$C$8,5,0))))) -> 0 | U24: =IF(I24=Lookups!$B$4,1,IF(I24=Lookups!$B$5,2,IF(I24=Lookups!$B$6,3,IF(I24=Lookups!$B$7,4,IF(I24=Lookups!$B$8,5,0))))) -> 0 | V24: =IF(J24=Lookups!$C$4,1,IF(J24=Lookups!$C$5,2,IF(J24=Lookups!$C$6,3,IF(J24=Lookups!$C$7,4,IF(J24=Lookups!$C$8,5,0))))) -> 0
C25: Infrequently used property access in the middle of the site may not be adequately monitored resulting in unsafe site entry | F25: =IF(P25*Q25=0,$S$14,VLOOKUP(Q25,Lookups!$D$4:$J$8,'Planning Phase'!P25+2)) -> Select L & C | K25: =IF(U25*V25=0,$S$14,VLOOKUP(V25,Lookups!$D$4:$J$8,'Planning Phase'!U25+2)) -> Select L & C | P25: =IF(D25=Lookups!$B$4,1,IF(D25=Lookups!$B$5,2,IF(D25=Lookups!$B$6,3,IF(D25=Lookups!$B$7,4,IF(D25=Lookups!$B$8,5,0))))) -> 0 | Q25: =IF(E25=Lookups!$C$4,1,IF(E25=Lookups!$C$5,2,IF(E25=Lookups!$C$6,3,IF(E25=Lookups!$C$7,4,IF(E25=Lookups!$C$8,5,0))))) -> 0 | U25: =IF(I25=Lookups!$B$4,1,IF(I25=Lookups!$B$5,2,IF(I25=Lookups!$B$6,3,IF(I25=Lookups!$B$7,4,IF(I25=Lookups!$B$8,5,0))))) -> 0 | V25: =IF(J25=Lookups!$C$4,1,IF(J25=Lookups!$C$5,2,IF(J25=Lookups!$C$6,3,IF(J25=Lookups!$C$7,4,IF(J25=Lookups!$C$8,5,0))))) -> 0
C26: Long queues combined with inadequate warning of traffic queue results in collision at end of queue | F26: =IF(P26*Q26=0,$S$14,VLOOKUP(Q26,Lookups!$D$4:$J$8,'Planning Phase'!P26+2)) -> Select L & C | K26: =IF(U26*V26=0,$S$14,VLOOKUP(V26,Lookups!$D$4:$J$8,'Planning Phase'!U26+2)) -> Select L & C | P26: =IF(D26=Lookups!$B$4,1,IF(D26=Lookups!$B$5,2,IF(D26=Lookups!$B$6,3,IF(D26=Lookups!$B$7,4,IF(D26=Lookups!$B$8,5,0))))) -> 0 | Q26: =IF(E26=Lookups!$C$4,1,IF(E26=Lookups!$C$5,2,IF(E26=Lookups!$C$6,3,IF(E26=Lookups!$C$7,4,IF(E26=Lookups!$C$8,5,0))))) -> 0 | U26: =IF(I26=Lookups!$B$4,1,IF(I26=Lookups!$B$5,2,IF(I26=Lookups!$B$6,3,IF(I26=Lookups!$B$7,4,IF(I26=Lookups!$B$8,5,0))))) -> 0 | V26: =IF(J26=Lookups!$C$4,1,IF(J26=Lookups!$C$5,2,IF(J26=Lookups!$C$6,3,IF(J26=Lookups!$C$7,4,IF(J26=Lookups!$C$8,5,0))))) -> 0
B27: Detouring of traffic from a major or multi-lane road | C27: Volume of detoured traffic has unacceptable impact on surrounding areas including - property and business access is compromised - Increased volume of traffic on residential streets leading to compromised safety outcomes for residents | F27: =IF(P27*Q27=0,$S$14,VLOOKUP(Q27,Lookups!$D$4:$J$8,'Planning Phase'!P27+2)) -> Select L & C | K27: =IF(U27*V27=0,$S$14,VLOOKUP(V27,Lookups!$D$4:$J$8,'Planning Phase'!U27+2)) -> Select L & C | P27: =IF(D27=Lookups!$B$4,1,IF(D27=Lookups!$B$5,2,IF(D27=Lookups!$B$6,3,IF(D27=Lookups!$B$7,4,IF(D27=Lookups!$B$8,5,0))))) -> 0 | Q27: =IF(E27=Lookups!$C$4,1,IF(E27=Lookups!$C$5,2,IF(E27=Lookups!$C$6,3,IF(E27=Lookups!$C$7,4,IF(E27=Lookups!$C$8,5,0))))) -> 0 | U27: =IF(I27=Lookups!$B$4,1,IF(I27=Lookups!$B$5,2,IF(I27=Lookups!$B$6,3,IF(I27=Lookups!$B$7,4,IF(I27=Lookups!$B$8,5,0))))) -> 0 | V27: =IF(J27=Lookups!$C$4,1,IF(J27=Lookups!$C$5,2,IF(J27=Lookups!$C$6,3,IF(J27=Lookups!$C$7,4,IF(J27=Lookups!$C$8,5,0))))) -> 0
C28: Detoured traffic experiences unacceptable delays | F28: =IF(P28*Q28=0,$S$14,VLOOKUP(Q28,Lookups!$D$4:$J$8,'Planning Phase'!P28+2)) -> Select L & C | K28: =IF(U28*V28=0,$S$14,VLOOKUP(V28,Lookups!$D$4:$J$8,'Planning Phase'!U28+2)) -> Select L & C | P28: =IF(D28=Lookups!$B$4,1,IF(D28=Lookups!$B$5,2,IF(D28=Lookups!$B$6,3,IF(D28=Lookups!$B$7,4,IF(D28=Lookups!$B$8,5,0))))) -> 0 | Q28: =IF(E28=Lookups!$C$4,1,IF(E28=Lookups!$C$5,2,IF(E28=Lookups!$C$6,3,IF(E28=Lookups!$C$7,4,IF(E28=Lookups!$C$8,5,0))))) -> 0 | U28: =IF(I28=Lookups!$B$4,1,IF(I28=Lookups!$B$5,2,IF(I28=Lookups!$B$6,3,IF(I28=Lookups!$B$7,4,IF(I28=Lookups!$B$8,5,0))))) -> 0 | V28: =IF(J28=Lookups!$C$4,1,IF(J28=Lookups!$C$5,2,IF(J28=Lookups!$C$6,3,IF(J28=Lookups!$C$7,4,IF(J28=Lookups!$C$8,5,0))))) -> 0
B29: Detouring of traffic onto roads with height, length or weight restrictions | C29: Some detoured vehicles cannot negotiate the defined detour creating - delays and congestion while reversing or turning - damage to infrastructure - collisions with other vehicles | F29: =IF(P29*Q29=0,$S$14,VLOOKUP(Q29,Lookups!$D$4:$J$8,'Planning Phase'!P29+2)) -> Select L & C | K29: =IF(U29*V29=0,$S$14,VLOOKUP(V29,Lookups!$D$4:$J$8,'Planning Phase'!U29+2)) -> Select L & C | P29: =IF(D29=Lookups!$B$4,1,IF(D29=Lookups!$B$5,2,IF(D29=Lookups!$B$6,3,IF(D29=Lookups!$B$7,4,IF(D29=Lookups!$B$8,5,0))))) -> 0 | Q29: =IF(E29=Lookups!$C$4,1,IF(E29=Lookups!$C$5,2,IF(E29=Lookups!$C$6,3,IF(E29=Lookups!$C$7,4,IF(E29=Lookups!$C$8,5,0))))) -> 0 | U29: =IF(I29=Lookups!$B$4,1,IF(I29=Lookups!$B$5,2,IF(I29=Lookups!$B$6,3,IF(I29=Lookups!$B$7,4,IF(I29=Lookups!$B$8,5,0))))) -> 0 | V29: =IF(J29=Lookups!$C$4,1,IF(J29=Lookups!$C$5,2,IF(J29=Lookups!$C$6,3,IF(J29=Lookups!$C$7,4,IF(J29=Lookups!$C$8,5,0))))) -> 0
B30: Works lead to excessive and unacceptable traffic queues and delays. Can be due to - not maintaining min available req. lanes - closure of high volume roads | C30: Aggressive driver behaviour and lack of community acceptance of worksite | F30: =IF(P30*Q30=0,$S$14,VLOOKUP(Q30,Lookups!$D$4:$J$8,'Planning Phase'!P30+2)) -> Select L & C | K30: =IF(U30*V30=0,$S$14,VLOOKUP(V30,Lookups!$D$4:$J$8,'Planning Phase'!U30+2)) -> Select L & C | P30: =IF(D30=Lookups!$B$4,1,IF(D30=Lookups!$B$5,2,IF(D30=Lookups!$B$6,3,IF(D30=Lookups!$B$7,4,IF(D30=Lookups!$B$8,5,0))))) -> 0 | Q30: =IF(E30=Lookups!$C$4,1,IF(E30=Lookups!$C$5,2,IF(E30=Lookups!$C$6,3,IF(E30=Lookups!$C$7,4,IF(E30=Lookups!$C$8,5,0))))) -> 0 | U30: =IF(I30=Lookups!$B$4,1,IF(I30=Lookups!$B$5,2,IF(I30=Lookups!$B$6,3,IF(I30=Lookups!$B$7,4,IF(I30=Lookups!$B$8,5,0))))) -> 0 | V30: =IF(J30=Lookups!$C$4,1,IF(J30=Lookups!$C$5,2,IF(J30=Lookups!$C$6,3,IF(J30=Lookups!$C$7,4,IF(J30=Lookups!$C$8,5,0))))) -> 0
C31: Traffic volumes not suitably accommodaed leading to congestion / delays exceeds allowable levels | F31: =IF(P31*Q31=0,$S$14,VLOOKUP(Q31,Lookups!$D$4:$J$8,'Planning Phase'!P31+2)) -> Select L & C | K31: =IF(U31*V31=0,$S$14,VLOOKUP(V31,Lookups!$D$4:$J$8,'Planning Phase'!U31+2)) -> Select L & C | P31: =IF(D31=Lookups!$B$4,1,IF(D31=Lookups!$B$5,2,IF(D31=Lookups!$B$6,3,IF(D31=Lookups!$B$7,4,IF(D31=Lookups!$B$8,5,0))))) -> 0 | Q31: =IF(E31=Lookups!$C$4,1,IF(E31=Lookups!$C$5,2,IF(E31=Lookups!$C$6,3,IF(E31=Lookups!$C$7,4,IF(E31=Lookups!$C$8,5,0))))) -> 0 | U31: =IF(I31=Lookups!$B$4,1,IF(I31=Lookups!$B$5,2,IF(I31=Lookups!$B$6,3,IF(I31=Lookups!$B$7,4,IF(I31=Lookups!$B$8,5,0))))) -> 0 | V31: =IF(J31=Lookups!$C$4,1,IF(J31=Lookups!$C$5,2,IF(J31=Lookups!$C$6,3,IF(J31=Lookups!$C$7,4,IF(J31=Lookups!$C$8,5,0))))) -> 0
C32: Extended queue lengths, or road alignment factors affect sight distance to the end of queue, leads to netowrk crash risks | F32: =IF(P32*Q32=0,$S$14,VLOOKUP(Q32,Lookups!$D$4:$J$8,'Planning Phase'!P32+2)) -> Select L & C | K32: =IF(U32*V32=0,$S$14,VLOOKUP(V32,Lookups!$D$4:$J$8,'Planning Phase'!U32+2)) -> Select L & C | P32: =IF(D32=Lookups!$B$4,1,IF(D32=Lookups!$B$5,2,IF(D32=Lookups!$B$6,3,IF(D32=Lookups!$B$7,4,IF(D32=Lookups!$B$8,5,0))))) -> 0 | Q32: =IF(E32=Lookups!$C$4,1,IF(E32=Lookups!$C$5,2,IF(E32=Lookups!$C$6,3,IF(E32=Lookups!$C$7,4,IF(E32=Lookups!$C$8,5,0))))) -> 0 | U32: =IF(I32=Lookups!$B$4,1,IF(I32=Lookups!$B$5,2,IF(I32=Lookups!$B$6,3,IF(I32=Lookups!$B$7,4,IF(I32=Lookups!$B$8,5,0))))) -> 0 | V32: =IF(J32=Lookups!$C$4,1,IF(J32=Lookups!$C$5,2,IF(J32=Lookups!$C$6,3,IF(J32=Lookups!$C$7,4,IF(J32=Lookups!$C$8,5,0))))) -> 0
C33: Volume of traffic in remaining lanes is unacceptably high leading to traffic queues extend through nearby intersections / roundabouts | F33: =IF(P33*Q33=0,$S$14,VLOOKUP(Q33,Lookups!$D$4:$J$8,'Planning Phase'!P33+2)) -> Select L & C | K33: =IF(U33*V33=0,$S$14,VLOOKUP(V33,Lookups!$D$4:$J$8,'Planning Phase'!U33+2)) -> Select L & C | P33: =IF(D33=Lookups!$B$4,1,IF(D33=Lookups!$B$5,2,IF(D33=Lookups!$B$6,3,IF(D33=Lookups!$B$7,4,IF(D33=Lookups!$B$8,5,0))))) -> 0 | Q33: =IF(E33=Lookups!$C$4,1,IF(E33=Lookups!$C$5,2,IF(E33=Lookups!$C$6,3,IF(E33=Lookups!$C$7,4,IF(E33=Lookups!$C$8,5,0))))) -> 0 | U33: =IF(I33=Lookups!$B$4,1,IF(I33=Lookups!$B$5,2,IF(I33=Lookups!$B$6,3,IF(I33=Lookups!$B$7,4,IF(I33=Lookups!$B$8,5,0))))) -> 0 | V33: =IF(J33=Lookups!$C$4,1,IF(J33=Lookups!$C$5,2,IF(J33=Lookups!$C$6,3,IF(J33=Lookups!$C$7,4,IF(J33=Lookups!$C$8,5,0))))) -> 0
B34: Interference with the operation of permanent traffic signals | C34: Compromised legibility of traffic controls for road users leads to road user confusion leading to increased likelihood of traffic incidents | F34: =IF(P34*Q34=0,$S$14,VLOOKUP(Q34,Lookups!$D$4:$J$8,'Planning Phase'!P34+2)) -> Select L & C | K34: =IF(U34*V34=0,$S$14,VLOOKUP(V34,Lookups!$D$4:$J$8,'Planning Phase'!U34+2)) -> Select L & C | P34: =IF(D34=Lookups!$B$4,1,IF(D34=Lookups!$B$5,2,IF(D34=Lookups!$B$6,3,IF(D34=Lookups!$B$7,4,IF(D34=Lookups!$B$8,5,0))))) -> 0 | Q34: =IF(E34=Lookups!$C$4,1,IF(E34=Lookups!$C$5,2,IF(E34=Lookups!$C$6,3,IF(E34=Lookups!$C$7,4,IF(E34=Lookups!$C$8,5,0))))) -> 0 | U34: =IF(I34=Lookups!$B$4,1,IF(I34=Lookups!$B$5,2,IF(I34=Lookups!$B$6,3,IF(I34=Lookups!$B$7,4,IF(I34=Lookups!$B$8,5,0))))) -> 0 | V34: =IF(J34=Lookups!$C$4,1,IF(J34=Lookups!$C$5,2,IF(J34=Lookups!$C$6,3,IF(J34=Lookups!$C$7,4,IF(J34=Lookups!$C$8,5,0))))) -> 0
C35: Increased congestion due to works results in queued traffic through signalised intersections leading to unsafe operation of the intersection | F35: =IF(P35*Q35=0,$S$14,VLOOKUP(Q35,Lookups!$D$4:$J$8,'Planning Phase'!P35+2)) -> Select L & C | K35: =IF(U35*V35=0,$S$14,VLOOKUP(V35,Lookups!$D$4:$J$8,'Planning Phase'!U35+2)) -> Select L & C | P35: =IF(D35=Lookups!$B$4,1,IF(D35=Lookups!$B$5,2,IF(D35=Lookups!$B$6,3,IF(D35=Lookups!$B$7,4,IF(D35=Lookups!$B$8,5,0))))) -> 0 | Q35: =IF(E35=Lookups!$C$4,1,IF(E35=Lookups!$C$5,2,IF(E35=Lookups!$C$6,3,IF(E35=Lookups!$C$7,4,IF(E35=Lookups!$C$8,5,0))))) -> 0 | U35: =IF(I35=Lookups!$B$4,1,IF(I35=Lookups!$B$5,2,IF(I35=Lookups!$B$6,3,IF(I35=Lookups!$B$7,4,IF(I35=Lookups!$B$8,5,0))))) -> 0 | V35: =IF(J35=Lookups!$C$4,1,IF(J35=Lookups!$C$5,2,IF(J35=Lookups!$C$6,3,IF(J35=Lookups!$C$7,4,IF(J35=Lookups!$C$8,5,0))))) -> 0
B36: Closure of turning movements and banning of movements at intersections | C36: Closure of turning movements with no clear alternative leads to road user confusion and increased likelihood of traffic incidents | F36: =IF(P36*Q36=0,$S$14,VLOOKUP(Q36,Lookups!$D$4:$J$8,'Planning Phase'!P36+2)) -> Select L & C | K36: =IF(U36*V36=0,$S$14,VLOOKUP(V36,Lookups!$D$4:$J$8,'Planning Phase'!U36+2)) -> Select L & C | P36: =IF(D36=Lookups!$B$4,1,IF(D36=Lookups!$B$5,2,IF(D36=Lookups!$B$6,3,IF(D36=Lookups!$B$7,4,IF(D36=Lookups!$B$8,5,0))))) -> 0 | Q36: =IF(E36=Lookups!$C$4,1,IF(E36=Lookups!$C$5,2,IF(E36=Lookups!$C$6,3,IF(E36=Lookups!$C$7,4,IF(E36=Lookups!$C$8,5,0))))) -> 0 | U36: =IF(I36=Lookups!$B$4,1,IF(I36=Lookups!$B$5,2,IF(I36=Lookups!$B$6,3,IF(I36=Lookups!$B$7,4,IF(I36=Lookups!$B$8,5,0))))) -> 0 | V36: =IF(J36=Lookups!$C$4,1,IF(J36=Lookups!$C$5,2,IF(J36=Lookups!$C$6,3,IF(J36=Lookups!$C$7,4,IF(J36=Lookups!$C$8,5,0))))) -> 0
C37: Volume of detoured traffic has unacceptable impact on surrounding areas including - property and business access is compromised - Increased congestion on other parts of the road network leading to compromised safety outcomes | F37: =IF(P37*Q37=0,$S$14,VLOOKUP(Q37,Lookups!$D$4:$J$8,'Planning Phase'!P37+2)) -> Select L & C | K37: =IF(U37*V37=0,$S$14,VLOOKUP(V37,Lookups!$D$4:$J$8,'Planning Phase'!U37+2)) -> Select L & C | P37: =IF(D37=Lookups!$B$4,1,IF(D37=Lookups!$B$5,2,IF(D37=Lookups!$B$6,3,IF(D37=Lookups!$B$7,4,IF(D37=Lookups!$B$8,5,0))))) -> 0 | Q37: =IF(E37=Lookups!$C$4,1,IF(E37=Lookups!$C$5,2,IF(E37=Lookups!$C$6,3,IF(E37=Lookups!$C$7,4,IF(E37=Lookups!$C$8,5,0))))) -> 0 | U37: =IF(I37=Lookups!$B$4,1,IF(I37=Lookups!$B$5,2,IF(I37=Lookups!$B$6,3,IF(I37=Lookups!$B$7,4,IF(I37=Lookups!$B$8,5,0))))) -> 0 | V37: =IF(J37=Lookups!$C$4,1,IF(J37=Lookups!$C$5,2,IF(J37=Lookups!$C$6,3,IF(J37=Lookups!$C$7,4,IF(J37=Lookups!$C$8,5,0))))) -> 0
B38: Speed choices | P38: =IF(D38=Lookups!$B$4,1,IF(D38=Lookups!$B$5,2,IF(D38=Lookups!$B$6,3,IF(D38=Lookups!$B$7,4,IF(D38=Lookups!$B$8,5,0))))) -> 0 | Q38: =IF(E38=Lookups!$C$4,1,IF(E38=Lookups!$C$5,2,IF(E38=Lookups!$C$6,3,IF(E38=Lookups!$C$7,4,IF(E38=Lookups!$C$8,5,0))))) -> 0 | U38: =IF(I38=Lookups!$B$4,1,IF(I38=Lookups!$B$5,2,IF(I38=Lookups!$B$6,3,IF(I38=Lookups!$B$7,4,IF(I38=Lookups!$B$8,5,0))))) -> 0 | V38: =IF(J38=Lookups!$C$4,1,IF(J38=Lookups!$C$5,2,IF(J38=Lookups!$C$6,3,IF(J38=Lookups!$C$7,4,IF(J38=Lookups!$C$8,5,0))))) -> 0
B39: Reductions in speed limits, considering the safety of workers and road users are not considered credible to drivers | C39: Road users travel at inappropriate speeds due to lack of understanding of applicable speed limits leads to increased likelihood and severity of incidents | F39: =IF(P39*Q39=0,$S$14,VLOOKUP(Q39,Lookups!$D$4:$J$8,'Planning Phase'!P39+2)) -> Select L & C | K39: =IF(U39*V39=0,$S$14,VLOOKUP(V39,Lookups!$D$4:$J$8,'Planning Phase'!U39+2)) -> Select L & C | P39: =IF(D39=Lookups!$B$4,1,IF(D39=Lookups!$B$5,2,IF(D39=Lookups!$B$6,3,IF(D39=Lookups!$B$7,4,IF(D39=Lookups!$B$8,5,0))))) -> 0 | Q39: =IF(E39=Lookups!$C$4,1,IF(E39=Lookups!$C$5,2,IF(E39=Lookups!$C$6,3,IF(E39=Lookups!$C$7,4,IF(E39=Lookups!$C$8,5,0))))) -> 0 | U39: =IF(I39=Lookups!$B$4,1,IF(I39=Lookups!$B$5,2,IF(I39=Lookups!$B$6,3,IF(I39=Lookups!$B$7,4,IF(I39=Lookups!$B$8,5,0))))) -> 0 | V39: =IF(J39=Lookups!$C$4,1,IF(J39=Lookups!$C$5,2,IF(J39=Lookups!$C$6,3,IF(J39=Lookups!$C$7,4,IF(J39=Lookups!$C$8,5,0))))) -> 0
B40: Special work speed limits less than 40km/h required for specific hazards | C40: Road users travel at inappropriate speeds due to lack of understanding of applicable speed limits leads to increased likelihood and severity of incidents | F40: =IF(P40*Q40=0,$S$14,VLOOKUP(Q40,Lookups!$D$4:$J$8,'Planning Phase'!P40+2)) -> Select L & C | K40: =IF(U40*V40=0,$S$14,VLOOKUP(V40,Lookups!$D$4:$J$8,'Planning Phase'!U40+2)) -> Select L & C | P40: =IF(D40=Lookups!$B$4,1,IF(D40=Lookups!$B$5,2,IF(D40=Lookups!$B$6,3,IF(D40=Lookups!$B$7,4,IF(D40=Lookups!$B$8,5,0))))) -> 0 | Q40: =IF(E40=Lookups!$C$4,1,IF(E40=Lookups!$C$5,2,IF(E40=Lookups!$C$6,3,IF(E40=Lookups!$C$7,4,IF(E40=Lookups!$C$8,5,0))))) -> 0 | U40: =IF(I40=Lookups!$B$4,1,IF(I40=Lookups!$B$5,2,IF(I40=Lookups!$B$6,3,IF(I40=Lookups!$B$7,4,IF(I40=Lookups!$B$8,5,0))))) -> 0 | V40: =IF(J40=Lookups!$C$4,1,IF(J40=Lookups!$C$5,2,IF(J40=Lookups!$C$6,3,IF(J40=Lookups!$C$7,4,IF(J40=Lookups!$C$8,5,0))))) -> 0
B41: Worksite operations | P41: =IF(D41=Lookups!$B$4,1,IF(D41=Lookups!$B$5,2,IF(D41=Lookups!$B$6,3,IF(D41=Lookups!$B$7,4,IF(D41=Lookups!$B$8,5,0))))) -> 0 | Q41: =IF(E41=Lookups!$C$4,1,IF(E41=Lookups!$C$5,2,IF(E41=Lookups!$C$6,3,IF(E41=Lookups!$C$7,4,IF(E41=Lookups!$C$8,5,0))))) -> 0 | U41: =IF(I41=Lookups!$B$4,1,IF(I41=Lookups!$B$5,2,IF(I41=Lookups!$B$6,3,IF(I41=Lookups!$B$7,4,IF(I41=Lookups!$B$8,5,0))))) -> 0 | V41: =IF(J41=Lookups!$C$4,1,IF(J41=Lookups!$C$5,2,IF(J41=Lookups!$C$6,3,IF(J41=Lookups!$C$7,4,IF(J41=Lookups!$C$8,5,0))))) -> 0
B42: Site in operation during times of night / low visibility | C42: Sight distance or vision of road user compromised on approach to worksite results in road user unable to respond in a timely manner to the hazard ahead | F42: =IF(P42*Q42=0,$S$14,VLOOKUP(Q42,Lookups!$D$4:$J$8,'Planning Phase'!P42+2)) -> Select L & C | K42: =IF(U42*V42=0,$S$14,VLOOKUP(V42,Lookups!$D$4:$J$8,'Planning Phase'!U42+2)) -> Select L & C | P42: =IF(D42=Lookups!$B$4,1,IF(D42=Lookups!$B$5,2,IF(D42=Lookups!$B$6,3,IF(D42=Lookups!$B$7,4,IF(D42=Lookups!$B$8,5,0))))) -> 0 | Q42: =IF(E42=Lookups!$C$4,1,IF(E42=Lookups!$C$5,2,IF(E42=Lookups!$C$6,3,IF(E42=Lookups!$C$7,4,IF(E42=Lookups!$C$8,5,0))))) -> 0 | U42: =IF(I42=Lookups!$B$4,1,IF(I42=Lookups!$B$5,2,IF(I42=Lookups!$B$6,3,IF(I42=Lookups!$B$7,4,IF(I42=Lookups!$B$8,5,0))))) -> 0 | V42: =IF(J42=Lookups!$C$4,1,IF(J42=Lookups!$C$5,2,IF(J42=Lookups!$C$6,3,IF(J42=Lookups!$C$7,4,IF(J42=Lookups!$C$8,5,0))))) -> 0
B43: Periods in which work can and cannot occur | C43: Work occurs at inappropriate times of the day - Disruption of residential areas - Interference with known peak traffic times - Frequent interference with usual business activity - Dust and noise impacts on surrounding areas | F43: =IF(P43*Q43=0,$S$14,VLOOKUP(Q43,Lookups!$D$4:$J$8,'Planning Phase'!P43+2)) -> Select L & C | K43: =IF(U43*V43=0,$S$14,VLOOKUP(V43,Lookups!$D$4:$J$8,'Planning Phase'!U43+2)) -> Select L & C | P43: =IF(D43=Lookups!$B$4,1,IF(D43=Lookups!$B$5,2,IF(D43=Lookups!$B$6,3,IF(D43=Lookups!$B$7,4,IF(D43=Lookups!$B$8,5,0))))) -> 0 | Q43: =IF(E43=Lookups!$C$4,1,IF(E43=Lookups!$C$5,2,IF(E43=Lookups!$C$6,3,IF(E43=Lookups!$C$7,4,IF(E43=Lookups!$C$8,5,0))))) -> 0 | U43: =IF(I43=Lookups!$B$4,1,IF(I43=Lookups!$B$5,2,IF(I43=Lookups!$B$6,3,IF(I43=Lookups!$B$7,4,IF(I43=Lookups!$B$8,5,0))))) -> 0 | V43: =IF(J43=Lookups!$C$4,1,IF(J43=Lookups!$C$5,2,IF(J43=Lookups!$C$6,3,IF(J43=Lookups!$C$7,4,IF(J43=Lookups!$C$8,5,0))))) -> 0
B44: TMP implemention for excessive time within a single shift | C44: Staff fatigue leads to decreased concentration of road workers leading to increased likelihood of incidents | F44: =IF(P44*Q44=0,$S$14,VLOOKUP(Q44,Lookups!$D$4:$J$8,'Planning Phase'!P44+2)) -> Select L & C | K44: =IF(U44*V44=0,$S$14,VLOOKUP(V44,Lookups!$D$4:$J$8,'Planning Phase'!U44+2)) -> Select L & C | P44: =IF(D44=Lookups!$B$4,1,IF(D44=Lookups!$B$5,2,IF(D44=Lookups!$B$6,3,IF(D44=Lookups!$B$7,4,IF(D44=Lookups!$B$8,5,0))))) -> 0 | Q44: =IF(E44=Lookups!$C$4,1,IF(E44=Lookups!$C$5,2,IF(E44=Lookups!$C$6,3,IF(E44=Lookups!$C$7,4,IF(E44=Lookups!$C$8,5,0))))) -> 0 | U44: =IF(I44=Lookups!$B$4,1,IF(I44=Lookups!$B$5,2,IF(I44=Lookups!$B$6,3,IF(I44=Lookups!$B$7,4,IF(I44=Lookups!$B$8,5,0))))) -> 0 | V44: =IF(J44=Lookups!$C$4,1,IF(J44=Lookups!$C$5,2,IF(J44=Lookups!$C$6,3,IF(J44=Lookups!$C$7,4,IF(J44=Lookups!$C$8,5,0))))) -> 0
B45: Emergency Vehicles | P45: =IF(D45=Lookups!$B$4,1,IF(D45=Lookups!$B$5,2,IF(D45=Lookups!$B$6,3,IF(D45=Lookups!$B$7,4,IF(D45=Lookups!$B$8,5,0))))) -> 0 | Q45: =IF(E45=Lookups!$C$4,1,IF(E45=Lookups!$C$5,2,IF(E45=Lookups!$C$6,3,IF(E45=Lookups!$C$7,4,IF(E45=Lookups!$C$8,5,0))))) -> 0 | U45: =IF(I45=Lookups!$B$4,1,IF(I45=Lookups!$B$5,2,IF(I45=Lookups!$B$6,3,IF(I45=Lookups!$B$7,4,IF(I45=Lookups!$B$8,5,0))))) -> 0 | V45: =IF(J45=Lookups!$C$4,1,IF(J45=Lookups!$C$5,2,IF(J45=Lookups!$C$6,3,IF(J45=Lookups!$C$7,4,IF(J45=Lookups!$C$8,5,0))))) -> 0
B46: Works lead to excessive traffic queues and delays leads to unacceptably long delays to road users | C46: Emergency vehicles access past the works area is blocked by works activities or queued traffic leading to unacceptable delays to emergency vehicles | F46: =IF(P46*Q46=0,$S$14,VLOOKUP(Q46,Lookups!$D$4:$J$8,'Planning Phase'!P46+2)) -> Select L & C | K46: =IF(U46*V46=0,$S$14,VLOOKUP(V46,Lookups!$D$4:$J$8,'Planning Phase'!U46+2)) -> Select L & C | P46: =IF(D46=Lookups!$B$4,1,IF(D46=Lookups!$B$5,2,IF(D46=Lookups!$B$6,3,IF(D46=Lookups!$B$7,4,IF(D46=Lookups!$B$8,5,0))))) -> 0 | Q46: =IF(E46=Lookups!$C$4,1,IF(E46=Lookups!$C$5,2,IF(E46=Lookups!$C$6,3,IF(E46=Lookups!$C$7,4,IF(E46=Lookups!$C$8,5,0))))) -> 0 | U46: =IF(I46=Lookups!$B$4,1,IF(I46=Lookups!$B$5,2,IF(I46=Lookups!$B$6,3,IF(I46=Lookups!$B$7,4,IF(I46=Lookups!$B$8,5,0))))) -> 0 | V46: =IF(J46=Lookups!$C$4,1,IF(J46=Lookups!$C$5,2,IF(J46=Lookups!$C$6,3,IF(J46=Lookups!$C$7,4,IF(J46=Lookups!$C$8,5,0))))) -> 0
...

Sheet Design Phase
B7: Risk | D7: Initial Risk | G7: Proposed Control Measures | I7: Revised Risk | L7: Selected | M7: Actions | P7: Initial Scores | U7: Initial Scores
B8: Source | C8: Event | D8: Likelihood | E8: Consequence | F8: Rating | G8: Options | H8: Considerations | I8: Likelihood | J8: Consequence | K8: Rating | M8: Who | N8: What | P8: L | Q8: C | U8: L | V8: C
B9: Vulnerable Road Users - pedestrians, cyclists, people with disabilities and wheeled path users | S9: Very High
B10: Planning Phase items - need to be considered/reviewed in design phase as well unless closed out or deemed not applicable in planning phase
B11: Works impact on existing path routes resulting in VRU unable to pass the site safely using existing paths | C11: VRUs cross roads in an unsafe manner at unsigned locations | F11: =IF(P11*Q11=0,$S$15,VLOOKUP(Q11,Lookups!$D$4:$J$8,'Design Phase'!P11+2)) -> Select L & C | K11: =IF(U11*V11=0,$S$15,VLOOKUP(V11,Lookups!$D$4:$J$8,'Design Phase'!U11+2)) -> Select L & C | P11: =IF(D11=Lookups!$B$4,1,IF(D11=Lookups!$B$5,2,IF(D11=Lookups!$B$6,3,IF(D11=Lookups!$B$7,4,IF(D11=Lookups!$B$8,5,0))))) -> 0 | Q11: =IF(E11=Lookups!$C$4,1,IF(E11=Lookups!$C$5,2,IF(E11=Lookups!$C$6,3,IF(E11=Lookups!$C$7,4,IF(E11=Lookups!$C$8,5,0))))) -> 0 | S11: High | U11: =IF(I11=Lookups!$B$4,1,IF(I11=Lookups!$B$5,2,IF(I11=Lookups!$B$6,3,IF(I11=Lookups!$B$7,4,IF(I11=Lookups!$B$8,5,0))))) -> 0 | V11: =IF(J11=Lookups!$C$4,1,IF(J11=Lookups!$C$5,2,IF(J11=Lookups!$C$6,3,IF(J11=Lookups!$C$7,4,IF(J11=Lookups!$C$8,5,0))))) -> 0
C12: VRUs use a temporary path route which has a surface not appropriate for wheeled path users, visually impaired and VRU with mobility issues. Results in trip or fall hazards | F12: =IF(P12*Q12=0,$S$15,VLOOKUP(Q12,Lookups!$D$4:$J$8,'Design Phase'!P12+2)) -> Select L & C | K12: =IF(U12*V12=0,$S$15,VLOOKUP(V12,Lookups!$D$4:$J$8,'Design Phase'!U12+2)) -> Select L & C | P12: =IF(D12=Lookups!$B$4,1,IF(D12=Lookups!$B$5,2,IF(D12=Lookups!$B$6,3,IF(D12=Lookups!$B$7,4,IF(D12=Lookups!$B$8,5,0))))) -> 0 | Q12: =IF(E12=Lookups!$C$4,1,IF(E12=Lookups!$C$5,2,IF(E12=Lookups!$C$6,3,IF(E12=Lookups!$C$7,4,IF(E12=Lookups!$C$8,5,0))))) -> 0 | S12: Medium | U12: =IF(I12=Lookups!$B$4,1,IF(I12=Lookups!$B$5,2,IF(I12=Lookups!$B$6,3,IF(I12=Lookups!$B$7,4,IF(I12=Lookups!$B$8,5,0))))) -> 0 | V12: =IF(J12=Lookups!$C$4,1,IF(J12=Lookups!$C$5,2,IF(J12=Lookups!$C$6,3,IF(J12=Lookups!$C$7,4,IF(J12=Lookups!$C$8,5,0))))) -> 0
C13: VRUs diverted to a detour route which is an unacceptable length with a lower likelihood of VRUs using the defined route | F13: =IF(P13*Q13=0,$S$15,VLOOKUP(Q13,Lookups!$D$4:$J$8,'Design Phase'!P13+2)) -> Select L & C | K13: =IF(U13*V13=0,$S$15,VLOOKUP(V13,Lookups!$D$4:$J$8,'Design Phase'!U13+2)) -> Select L & C | P13: =IF(D13=Lookups!$B$4,1,IF(D13=Lookups!$B$5,2,IF(D13=Lookups!$B$6,3,IF(D13=Lookups!$B$7,4,IF(D13=Lookups!$B$8,5,0))))) -> 0 | Q13: =IF(E13=Lookups!$C$4,1,IF(E13=Lookups!$C$5,2,IF(E13=Lookups!$C$6,3,IF(E13=Lookups!$C$7,4,IF(E13=Lookups!$C$8,5,0))))) -> 0 | S13: Low | U13: =IF(I13=Lookups!$B$4,1,IF(I13=Lookups!$B$5,2,IF(I13=Lookups!$B$6,3,IF(I13=Lookups!$B$7,4,IF(I13=Lookups!$B$8,5,0))))) -> 0 | V13: =IF(J13=Lookups!$C$4,1,IF(J13=Lookups!$C$5,2,IF(J13=Lookups!$C$6,3,IF(J13=Lookups!$C$7,4,IF(J13=Lookups!$C$8,5,0))))) -> 0
C14: VRUs following unfamiliar and illegible paths due to lack of clear direction interact with work site vehicles, equipment or other vehicles moving through the site. | F14: =IF(P14*Q14=0,$S$15,VLOOKUP(Q14,Lookups!$D$4:$J$8,'Design Phase'!P14+2)) -> Select L & C | K14: =IF(U14*V14=0,$S$15,VLOOKUP(V14,Lookups!$D$4:$J$8,'Design Phase'!U14+2)) -> Select L & C | P14: =IF(D14=Lookups!$B$4,1,IF(D14=Lookups!$B$5,2,IF(D14=Lookups!$B$6,3,IF(D14=Lookups!$B$7,4,IF(D14=Lookups!$B$8,5,0))))) -> 0 | Q14: =IF(E14=Lookups!$C$4,1,IF(E14=Lookups!$C$5,2,IF(E14=Lookups!$C$6,3,IF(E14=Lookups!$C$7,4,IF(E14=Lookups!$C$8,5,0))))) -> 0 | S14: Negligible | U14: =IF(I14=Lookups!$B$4,1,IF(I14=Lookups!$B$5,2,IF(I14=Lookups!$B$6,3,IF(I14=Lookups!$B$7,4,IF(I14=Lookups!$B$8,5,0))))) -> 0 | V14: =IF(J14=Lookups!$C$4,1,IF(J14=Lookups!$C$5,2,IF(J14=Lookups!$C$6,3,IF(J14=Lookups!$C$7,4,IF(J14=Lookups!$C$8,5,0))))) -> 0
C15: VRUs confused by TTM layout and follow incorrect route into site | F15: =IF(P15*Q15=0,$S$15,VLOOKUP(Q15,Lookups!$D$4:$J$8,'Design Phase'!P15+2)) -> Select L & C | K15: =IF(U15*V15=0,$S$15,VLOOKUP(V15,Lookups!$D$4:$J$8,'Design Phase'!U15+2)) -> Select L & C | P15: =IF(D15=Lookups!$B$4,1,IF(D15=Lookups!$B$5,2,IF(D15=Lookups!$B$6,3,IF(D15=Lookups!$B$7,4,IF(D15=Lookups!$B$8,5,0))))) -> 0 | Q15: =IF(E15=Lookups!$C$4,1,IF(E15=Lookups!$C$5,2,IF(E15=Lookups!$C$6,3,IF(E15=Lookups!$C$7,4,IF(E15=Lookups!$C$8,5,0))))) -> 0 | S15: =IF(AC15*AD15=0,"Select L & C",VLOOKUP(AD15,Lookups!Q8:W12,'Design Phase'!AC15+2)) -> Select L & C | U15: =IF(I15=Lookups!$B$4,1,IF(I15=Lookups!$B$5,2,IF(I15=Lookups!$B$6,3,IF(I15=Lookups!$B$7,4,IF(I15=Lookups!$B$8,5,0))))) -> 0 | V15: =IF(J15=Lookups!$C$4,1,IF(J15=Lookups!$C$5,2,IF(J15=Lookups!$C$6,3,IF(J15=Lookups!$C$7,4,IF(J15=Lookups!$C$8,5,0))))) -> 0
C16: VRUs entering live traffic lanes in unsafe locations | F16: =IF(P16*Q16=0,$S$15,VLOOKUP(Q16,Lookups!$D$4:$J$8,'Design Phase'!P16+2)) -> Select L & C | K16: =IF(U16*V16=0,$S$15,VLOOKUP(V16,Lookups!$D$4:$J$8,'Design Phase'!U16+2)) -> Select L & C | P16: =IF(D16=Lookups!$B$4,1,IF(D16=Lookups!$B$5,2,IF(D16=Lookups!$B$6,3,IF(D16=Lookups!$B$7,4,IF(D16=Lookups!$B$8,5,0))))) -> 0 | Q16: =IF(E16=Lookups!$C$4,1,IF(E16=Lookups!$C$5,2,IF(E16=Lookups!$C$6,3,IF(E16=Lookups!$C$7,4,IF(E16=Lookups!$C$8,5,0))))) -> 0 | U16: =IF(I16=Lookups!$B$4,1,IF(I16=Lookups!$B$5,2,IF(I16=Lookups!$B$6,3,IF(I16=Lookups!$B$7,4,IF(I16=Lookups!$B$8,5,0))))) -> 0 | V16: =IF(J16=Lookups!$C$4,1,IF(J16=Lookups!$C$5,2,IF(J16=Lookups!$C$6,3,IF(J16=Lookups!$C$7,4,IF(J16=Lookups!$C$8,5,0))))) -> 0
C17: VRUs confused by TTM layout or path direction is not clear - and follow unsafe route around site | F17: =IF(P17*Q17=0,$S$15,VLOOKUP(Q17,Lookups!$D$4:$J$8,'Design Phase'!P17+2)) -> Select L & C | K17: =IF(U17*V17=0,$S$15,VLOOKUP(V17,Lookups!$D$4:$J$8,'Design Phase'!U17+2)) -> Select L & C | P17: =IF(D17=Lookups!$B$4,1,IF(D17=Lookups!$B$5,2,IF(D17=Lookups!$B$6,3,IF(D17=Lookups!$B$7,4,IF(D17=Lookups!$B$8,5,0))))) -> 0 | Q17: =IF(E17=Lookups!$C$4,1,IF(E17=Lookups!$C$5,2,IF(E17=Lookups!$C$6,3,IF(E17=Lookups!$C$7,4,IF(E17=Lookups!$C$8,5,0))))) -> 0 | U17: =IF(I17=Lookups!$B$4,1,IF(I17=Lookups!$B$5,2,IF(I17=Lookups!$B$6,3,IF(I17=Lookups!$B$7,4,IF(I17=Lookups!$B$8,5,0))))) -> 0 | V17: =IF(J17=Lookups!$C$4,1,IF(J17=Lookups!$C$5,2,IF(J17=Lookups!$C$6,3,IF(J17=Lookups!$C$7,4,IF(J17=Lookups!$C$8,5,0))))) -> 0
B18: Works impact on existing crossings resulting in VRU unable to use the existing crossing route | C18: Altered crossing is not clear to path users leading to unpredictable pedestrian behaviour when crossing roads | F18: =IF(P18*Q18=0,$S$15,VLOOKUP(Q18,Lookups!$D$4:$J$8,'Design Phase'!P18+2)) -> Select L & C | K18: =IF(U18*V18=0,$S$15,VLOOKUP(V18,Lookups!$D$4:$J$8,'Design Phase'!U18+2)) -> Select L & C | P18: =IF(D18=Lookups!$B$4,1,IF(D18=Lookups!$B$5,2,IF(D18=Lookups!$B$6,3,IF(D18=Lookups!$B$7,4,IF(D18=Lookups!$B$8,5,0))))) -> 0 | Q18: =IF(E18=Lookups!$C$4,1,IF(E18=Lookups!$C$5,2,IF(E18=Lookups!$C$6,3,IF(E18=Lookups!$C$7,4,IF(E18=Lookups!$C$8,5,0))))) -> 0 | U18: =IF(I18=Lookups!$B$4,1,IF(I18=Lookups!$B$5,2,IF(I18=Lookups!$B$6,3,IF(I18=Lookups!$B$7,4,IF(I18=Lookups!$B$8,5,0))))) -> 0 | V18: =IF(J18=Lookups!$C$4,1,IF(J18=Lookups!$C$5,2,IF(J18=Lookups!$C$6,3,IF(J18=Lookups!$C$7,4,IF(J18=Lookups!$C$8,5,0))))) -> 0
C19: Safe school crossing practices compromised resulting in children crossing the road in an an unsafe and unpredictable manner in and around the site | F19: =IF(P19*Q19=0,$S$15,VLOOKUP(Q19,Lookups!$D$4:$J$8,'Design Phase'!P19+2)) -> Select L & C | K19: =IF(U19*V19=0,$S$15,VLOOKUP(V19,Lookups!$D$4:$J$8,'Design Phase'!U19+2)) -> Select L & C | P19: =IF(D19=Lookups!$B$4,1,IF(D19=Lookups!$B$5,2,IF(D19=Lookups!$B$6,3,IF(D19=Lookups!$B$7,4,IF(D19=Lookups!$B$8,5,0))))) -> 0 | Q19: =IF(E19=Lookups!$C$4,1,IF(E19=Lookups!$C$5,2,IF(E19=Lookups!$C$6,3,IF(E19=Lookups!$C$7,4,IF(E19=Lookups!$C$8,5,0))))) -> 0 | U19: =IF(I19=Lookups!$B$4,1,IF(I19=Lookups!$B$5,2,IF(I19=Lookups!$B$6,3,IF(I19=Lookups!$B$7,4,IF(I19=Lookups!$B$8,5,0))))) -> 0 | V19: =IF(J19=Lookups!$C$4,1,IF(J19=Lookups!$C$5,2,IF(J19=Lookups!$C$6,3,IF(J19=Lookups!$C$7,4,IF(J19=Lookups!$C$8,5,0))))) -> 0
B20: Schools, clubs or other facilities that may generate high volumes of pedestrian or cycle traffic | C20: Temporary or impacted path route has inadequate capacity leading to VRUs crossing at unsafe locations or travelling along the road leading to conflicts between path users and traffic, or to conflicts between VRUs and worksite hazards, plant movements or unsuitable routes | F20: =IF(P20*Q20=0,$S$15,VLOOKUP(Q20,Lookups!$D$4:$J$8,'Design Phase'!P20+2)) -> Select L & C | K20: =IF(U20*V20=0,$S$15,VLOOKUP(V20,Lookups!$D$4:$J$8,'Design Phase'!U20+2)) -> Select L & C | P20: =IF(D20=Lookups!$B$4,1,IF(D20=Lookups!$B$5,2,IF(D20=Lookups!$B$6,3,IF(D20=Lookups!$B$7,4,IF(D20=Lookups!$B$8,5,0))))) -> 0 | Q20: =IF(E20=Lookups!$C$4,1,IF(E20=Lookups!$C$5,2,IF(E20=Lookups!$C$6,3,IF(E20=Lookups!$C$7,4,IF(E20=Lookups!$C$8,5,0))))) -> 0 | U20: =IF(I20=Lookups!$B$4,1,IF(I20=Lookups!$B$5,2,IF(I20=Lookups!$B$6,3,IF(I20=Lookups!$B$7,4,IF(I20=Lookups!$B$8,5,0))))) -> 0 | V20: =IF(J20=Lookups!$C$4,1,IF(J20=Lookups!$C$5,2,IF(J20=Lookups!$C$6,3,IF(J20=Lookups!$C$7,4,IF(J20=Lookups!$C$8,5,0))))) -> 0
B21: Facilities such as hotels or taverns where pedestrians may have their judgement impaired | C21: VRUs may be confused by temporary alternative routes and enter the worksite of live traffic lanes at unsafe locations | F21: =IF(P21*Q21=0,$S$15,VLOOKUP(Q21,Lookups!$D$4:$J$8,'Design Phase'!P21+2)) -> Select L & C | K21: =IF(U21*V21=0,$S$15,VLOOKUP(V21,Lookups!$D$4:$J$8,'Design Phase'!U21+2)) -> Select L & C | P21: =IF(D21=Lookups!$B$4,1,IF(D21=Lookups!$B$5,2,IF(D21=Lookups!$B$6,3,IF(D21=Lookups!$B$7,4,IF(D21=Lookups!$B$8,5,0))))) -> 0 | Q21: =IF(E21=Lookups!$C$4,1,IF(E21=Lookups!$C$5,2,IF(E21=Lookups!$C$6,3,IF(E21=Lookups!$C$7,4,IF(E21=Lookups!$C$8,5,0))))) -> 0 | U21: =IF(I21=Lookups!$B$4,1,IF(I21=Lookups!$B$5,2,IF(I21=Lookups!$B$6,3,IF(I21=Lookups!$B$7,4,IF(I21=Lookups!$B$8,5,0))))) -> 0 | V21: =IF(J21=Lookups!$C$4,1,IF(J21=Lookups!$C$5,2,IF(J21=Lookups!$C$6,3,IF(J21=Lookups!$C$7,4,IF(J21=Lookups!$C$8,5,0))))) -> 0
B22: High cycle volumes on road or in defined bicycle lane / shoulder which is impacted by works | C22: Cyclist transition to footpath does not occur at a safe location leading to possible cyclist injury or conflict with other path users | F22: =IF(P22*Q22=0,$S$15,VLOOKUP(Q22,Lookups!$D$4:$J$8,'Design Phase'!P22+2)) -> Select L & C | K22: =IF(U22*V22=0,$S$15,VLOOKUP(V22,Lookups!$D$4:$J$8,'Design Phase'!U22+2)) -> Select L & C
C23: Cyclist merge with general traffic lanes at unsafe location or in unsafe manner leading to collision with other road vehicles. | F23: =IF(P23*Q23=0,$S$15,VLOOKUP(Q23,Lookups!$D$4:$J$8,'Design Phase'!P23+2)) -> Select L & C | K23: =IF(U23*V23=0,$S$15,VLOOKUP(V23,Lookups!$D$4:$J$8,'Design Phase'!U23+2)) -> Select L & C
B24: Additional design phase items
B25: Works impact on existing path routes - pedestrians diverted to alternative existing path routes | C25: Alternative path route is a lesser quality / standard than impacted route creating slip / trip / fall hazards for path users or hazards when path users need to pass each other - path width - path surface - path grade - lighting | F25: =IF(P25*Q25=0,$S$15,VLOOKUP(Q25,Lookups!$D$4:$J$8,'Design Phase'!P25+2)) -> Select L & C | K25: =IF(U25*V25=0,$S$15,VLOOKUP(V25,Lookups!$D$4:$J$8,'Design Phase'!U25+2)) -> Select L & C | P25: =IF(D25=Lookups!$B$4,1,IF(D25=Lookups!$B$5,2,IF(D25=Lookups!$B$6,3,IF(D25=Lookups!$B$7,4,IF(D25=Lookups!$B$8,5,0))))) -> 0 | Q25: =IF(E25=Lookups!$C$4,1,IF(E25=Lookups!$C$5,2,IF(E25=Lookups!$C$6,3,IF(E25=Lookups!$C$7,4,IF(E25=Lookups!$C$8,5,0))))) -> 0 | S25: High | U25: =IF(I25=Lookups!$B$4,1,IF(I25=Lookups!$B$5,2,IF(I25=Lookups!$B$6,3,IF(I25=Lookups!$B$7,4,IF(I25=Lookups!$B$8,5,0))))) -> 0 | V25: =IF(J25=Lookups!$C$4,1,IF(J25=Lookups!$C$5,2,IF(J25=Lookups!$C$6,3,IF(J25=Lookups!$C$7,4,IF(J25=Lookups!$C$8,5,0))))) -> 0
B26: Works impact on existing path routes - pedestrians diverted to temporary path routes | C26: Temporary path route is a lesser quality / standard than impacted route creating slip / trip / fall hazards for path users or hazards when path users need to pass each other - path width - path surface - path grade - lighting | F26: =IF(P26*Q26=0,$S$15,VLOOKUP(Q26,Lookups!$D$4:$J$8,'Design Phase'!P26+2)) -> Select L & C | K26: =IF(U26*V26=0,$S$15,VLOOKUP(V26,Lookups!$D$4:$J$8,'Design Phase'!U26+2)) -> Select L & C
B27: Works impact on existing path routes - pedestrians diverted to temporary route on the road surface | C27: Collision between diverted path users and traffic due to - inadequate separation between traffic and pedestrians - inadequate reduction in vehicle speeds past the worksite - inadequate protection / barriers to separate path from road | F27: =IF(P27*Q27=0,$S$15,VLOOKUP(Q27,Lookups!$D$4:$J$8,'Design Phase'!P27+2)) -> Select L & C
B28: Works impact on existing path routes - pedestrians diverted across roads at new or existing crossing points | C28: Alternative / Temporary crossing of roads creating conflict with traffic due to - inadequate controls for pedestrians in periods of high traffic - inadeqate sight distance at crossing points - indequate ramps / transition from path to road | F28: =IF(P28*Q28=0,$S$15,VLOOKUP(Q28,Lookups!$D$4:$J$8,'Design Phase'!P28+2)) -> Select L & C | K28: =IF(U28*V28=0,$S$15,VLOOKUP(V28,Lookups!$D$4:$J$8,'Design Phase'!U28+2)) -> Select L & C
B29: Temporary path route ot TTM devices restrict sight distances between pathways and intersections, driveways and site access points | C29: VRUs and/or drivers unable to see potential conflict situations leading to collisions | F29: =IF(P29*Q29=0,$S$15,VLOOKUP(Q29,Lookups!$D$4:$J$8,'Design Phase'!P29+2)) -> Select L & C | K29: =IF(U29*V29=0,$S$15,VLOOKUP(V29,Lookups!$D$4:$J$8,'Design Phase'!U29+2)) -> Select L & C
B30: TTM devices and signage are located in road shoulders, bicycle lanes, or immediately adjaent to paths | C30: Risk to cyclists using the road corridor - colliding with TTM devices - being diverted unsafely into traffic lanes - being diverted to alternative facilities at unsafe locations | F30: =IF(P30*Q30=0,$S$15,VLOOKUP(Q30,Lookups!$D$4:$J$8,'Design Phase'!P30+2)) -> Select L & C | K30: =IF(U30*V30=0,$S$15,VLOOKUP(V30,Lookups!$D$4:$J$8,'Design Phase'!U30+2)) -> Select L & C
B31: Traffic Impacts | P31: =IF(D31=Lookups!$B$4,1,IF(D31=Lookups!$B$5,2,IF(D31=Lookups!$B$6,3,IF(D31=Lookups!$B$7,4,IF(D31=Lookups!$B$8,5,0))))) -> 0 | Q31: =IF(E31=Lookups!$C$4,1,IF(E31=Lookups!$C$5,2,IF(E31=Lookups!$C$6,3,IF(E31=Lookups!$C$7,4,IF(E31=Lookups!$C$8,5,0))))) -> 0 | U31: =IF(I31=Lookups!$B$4,1,IF(I31=Lookups!$B$5,2,IF(I31=Lookups!$B$6,3,IF(I31=Lookups!$B$7,4,IF(I31=Lookups!$B$8,5,0))))) -> 0 | V31: =IF(J31=Lookups!$C$4,1,IF(J31=Lookups!$C$5,2,IF(J31=Lookups!$C$6,3,IF(J31=Lookups!$C$7,4,IF(J31=Lookups!$C$8,5,0))))) -> 0
B32: Planning Phase items - need to be considered/reviewed in design phase as well unless closed out or deemed not applicable in planning phase
B33: Excessive length of worksite, including rural areas | C33: Dangerous / agressive driver behaviour resulting from excessive length of queues because of time needed to manage reversible flow leading to lack of community / road user acceptance of the worksite | F33: =IF(P33*Q33=0,$S$15,VLOOKUP(Q33,Lookups!$D$4:$J$8,'Design Phase'!P33+2)) -> Select L & C | K33: =IF(U33*V33=0,$S$15,VLOOKUP(V33,Lookups!$D$4:$J$8,'Design Phase'!U33+2)) -> Select L & C | P33: =IF(D33=Lookups!$B$4,1,IF(D33=Lookups!$B$5,2,IF(D33=Lookups!$B$6,3,IF(D33=Lookups!$B$7,4,IF(D33=Lookups!$B$8,5,0))))) -> 0 | Q33: =IF(E33=Lookups!$C$4,1,IF(E33=Lookups!$C$5,2,IF(E33=Lookups!$C$6,3,IF(E33=Lookups!$C$7,4,IF(E33=Lookups!$C$8,5,0))))) -> 0 | U33: =IF(I33=Lookups!$B$4,1,IF(I33=Lookups!$B$5,2,IF(I33=Lookups!$B$6,3,IF(I33=Lookups!$B$7,4,IF(I33=Lookups!$B$8,5,0))))) -> 0 | V33: =IF(J33=Lookups!$C$4,1,IF(J33=Lookups!$C$5,2,IF(J33=Lookups!$C$6,3,IF(J33=Lookups!$C$7,4,IF(J33=Lookups!$C$8,5,0))))) -> 0
C34: Infrequently used property access in the middle of the site may not be adequately monitored resulting in unsafe site entry | F34: =IF(P34*Q34=0,$S$15,VLOOKUP(Q34,Lookups!$D$4:$J$8,'Design Phase'!P34+2)) -> Select L & C | K34: =IF(U34*V34=0,$S$15,VLOOKUP(V34,Lookups!$D$4:$J$8,'Design Phase'!U34+2)) -> Select L & C | P34: =IF(D34=Lookups!$B$4,1,IF(D34=Lookups!$B$5,2,IF(D34=Lookups!$B$6,3,IF(D34=Lookups!$B$7,4,IF(D34=Lookups!$B$8,5,0))))) -> 0 | Q34: =IF(E34=Lookups!$C$4,1,IF(E34=Lookups!$C$5,2,IF(E34=Lookups!$C$6,3,IF(E34=Lookups!$C$7,4,IF(E34=Lookups!$C$8,5,0))))) -> 0 | U34: =IF(I34=Lookups!$B$4,1,IF(I34=Lookups!$B$5,2,IF(I34=Lookups!$B$6,3,IF(I34=Lookups!$B$7,4,IF(I34=Lookups!$B$8,5,0))))) -> 0 | V34: =IF(J34=Lookups!$C$4,1,IF(J34=Lookups!$C$5,2,IF(J34=Lookups!$C$6,3,IF(J34=Lookups!$C$7,4,IF(J34=Lookups!$C$8,5,0))))) -> 0
C35: Long queues combined with inadequate warning of traffic queue results in collision at end of queue | F35: =IF(P35*Q35=0,$S$15,VLOOKUP(Q35,Lookups!$D$4:$J$8,'Design Phase'!P35+2)) -> Select L & C | K35: =IF(U35*V35=0,$S$15,VLOOKUP(V35,Lookups!$D$4:$J$8,'Design Phase'!U35+2)) -> Select L & C | P35: =IF(D35=Lookups!$B$4,1,IF(D35=Lookups!$B$5,2,IF(D35=Lookups!$B$6,3,IF(D35=Lookups!$B$7,4,IF(D35=Lookups!$B$8,5,0))))) -> 0 | Q35: =IF(E35=Lookups!$C$4,1,IF(E35=Lookups!$C$5,2,IF(E35=Lookups!$C$6,3,IF(E35=Lookups!$C$7,4,IF(E35=Lookups!$C$8,5,0))))) -> 0 | U35: =IF(I35=Lookups!$B$4,1,IF(I35=Lookups!$B$5,2,IF(I35=Lookups!$B$6,3,IF(I35=Lookups!$B$7,4,IF(I35=Lookups!$B$8,5,0))))) -> 0 | V35: =IF(J35=Lookups!$C$4,1,IF(J35=Lookups!$C$5,2,IF(J35=Lookups!$C$6,3,IF(J35=Lookups!$C$7,4,IF(J35=Lookups!$C$8,5,0))))) -> 0
B36: Detouring of traffic from a major or multi-lane road | C36: Volume of detoured traffic has unacceptable impact on surrounding areas including - property and business access is compromised - Increased volume of traffic on residential streets leading to compromised safety outcomes for residents | F36: =IF(P36*Q36=0,$S$15,VLOOKUP(Q36,Lookups!$D$4:$J$8,'Design Phase'!P36+2)) -> Select L & C | K36: =IF(U36*V36=0,$S$15,VLOOKUP(V36,Lookups!$D$4:$J$8,'Design Phase'!U36+2)) -> Select L & C | P36: =IF(D36=Lookups!$B$4,1,IF(D36=Lookups!$B$5,2,IF(D36=Lookups!$B$6,3,IF(D36=Lookups!$B$7,4,IF(D36=Lookups!$B$8,5,0))))) -> 0 | Q36: =IF(E36=Lookups!$C$4,1,IF(E36=Lookups!$C$5,2,IF(E36=Lookups!$C$6,3,IF(E36=Lookups!$C$7,4,IF(E36=Lookups!$C$8,5,0))))) -> 0 | U36: =IF(I36=Lookups!$B$4,1,IF(I36=Lookups!$B$5,2,IF(I36=Lookups!$B$6,3,IF(I36=Lookups!$B$7,4,IF(I36=Lookups!$B$8,5,0))))) -> 0 | V36: =IF(J36=Lookups!$C$4,1,IF(J36=Lookups!$C$5,2,IF(J36=Lookups!$C$6,3,IF(J36=Lookups!$C$7,4,IF(J36=Lookups!$C$8,5,0))))) -> 0
C37: Detoured traffic experiences unacceptable delays | F37: =IF(P37*Q37=0,$S$15,VLOOKUP(Q37,Lookups!$D$4:$J$8,'Design Phase'!P37+2)) -> Select L & C | K37: =IF(U37*V37=0,$S$15,VLOOKUP(V37,Lookups!$D$4:$J$8,'Design Phase'!U37+2)) -> Select L & C | P37: =IF(D37=Lookups!$B$4,1,IF(D37=Lookups!$B$5,2,IF(D37=Lookups!$B$6,3,IF(D37=Lookups!$B$7,4,IF(D37=Lookups!$B$8,5,0))))) -> 0 | Q37: =IF(E37=Lookups!$C$4,1,IF(E37=Lookups!$C$5,2,IF(E37=Lookups!$C$6,3,IF(E37=Lookups!$C$7,4,IF(E37=Lookups!$C$8,5,0))))) -> 0 | U37: =IF(I37=Lookups!$B$4,1,IF(I37=Lookups!$B$5,2,IF(I37=Lookups!$B$6,3,IF(I37=Lookups!$B$7,4,IF(I37=Lookups!$B$8,5,0))))) -> 0 | V37: =IF(J37=Lookups!$C$4,1,IF(J37=Lookups!$C$5,2,IF(J37=Lookups!$C$6,3,IF(J37=Lookups!$C$7,4,IF(J37=Lookups!$C$8,5,0))))) -> 0
B38: Works lead to excessive and unacceptable traffic queues and delays. Can be due to - not maintaining min available req. lanes - closure of high volume roads | C38: Aggressive driver behaviour and lack of community acceptance of worksite | F38: =IF(P38*Q38=0,$S$15,VLOOKUP(Q38,Lookups!$D$4:$J$8,'Design Phase'!P38+2)) -> Select L & C | K38: =IF(U38*V38=0,$S$15,VLOOKUP(V38,Lookups!$D$4:$J$8,'Design Phase'!U38+2)) -> Select L & C | P38: =IF(D38=Lookups!$B$4,1,IF(D38=Lookups!$B$5,2,IF(D38=Lookups!$B$6,3,IF(D38=Lookups!$B$7,4,IF(D38=Lookups!$B$8,5,0))))) -> 0 | Q38: =IF(E38=Lookups!$C$4,1,IF(E38=Lookups!$C$5,2,IF(E38=Lookups!$C$6,3,IF(E38=Lookups!$C$7,4,IF(E38=Lookups!$C$8,5,0))))) -> 0 | U38: =IF(I38=Lookups!$B$4,1,IF(I38=Lookups!$B$5,2,IF(I38=Lookups!$B$6,3,IF(I38=Lookups!$B$7,4,IF(I38=Lookups!$B$8,5,0))))) -> 0 | V38: =IF(J38=Lookups!$C$4,1,IF(J38=Lookups!$C$5,2,IF(J38=Lookups!$C$6,3,IF(J38=Lookups!$C$7,4,IF(J38=Lookups!$C$8,5,0))))) -> 0
C39: Traffic volumes not suitably accommodaed leading to congestion / delays exceeds allowable levels | F39: =IF(P39*Q39=0,$S$15,VLOOKUP(Q39,Lookups!$D$4:$J$8,'Design Phase'!P39+2)) -> Select L & C | K39: =IF(U39*V39=0,$S$15,VLOOKUP(V39,Lookups!$D$4:$J$8,'Design Phase'!U39+2)) -> Select L & C | P39: =IF(D39=Lookups!$B$4,1,IF(D39=Lookups!$B$5,2,IF(D39=Lookups!$B$6,3,IF(D39=Lookups!$B$7,4,IF(D39=Lookups!$B$8,5,0))))) -> 0 | Q39: =IF(E39=Lookups!$C$4,1,IF(E39=Lookups!$C$5,2,IF(E39=Lookups!$C$6,3,IF(E39=Lookups!$C$7,4,IF(E39=Lookups!$C$8,5,0))))) -> 0 | U39: =IF(I39=Lookups!$B$4,1,IF(I39=Lookups!$B$5,2,IF(I39=Lookups!$B$6,3,IF(I39=Lookups!$B$7,4,IF(I39=Lookups!$B$8,5,0))))) -> 0 | V39: =IF(J39=Lookups!$C$4,1,IF(J39=Lookups!$C$5,2,IF(J39=Lookups!$C$6,3,IF(J39=Lookups!$C$7,4,IF(J39=Lookups!$C$8,5,0))))) -> 0
C40: Extended queue lengths, or road alignment factors affect sight distance to the end of queue, leads to netowrk crash risks | F40: =IF(P40*Q40=0,$S$15,VLOOKUP(Q40,Lookups!$D$4:$J$8,'Design Phase'!P40+2)) -> Select L & C | K40: =IF(U40*V40=0,$S$15,VLOOKUP(V40,Lookups!$D$4:$J$8,'Design Phase'!U40+2)) -> Select L & C | P40: =IF(D40=Lookups!$B$4,1,IF(D40=Lookups!$B$5,2,IF(D40=Lookups!$B$6,3,IF(D40=Lookups!$B$7,4,IF(D40=Lookups!$B$8,5,0))))) -> 0 | Q40: =IF(E40=Lookups!$C$4,1,IF(E40=Lookups!$C$5,2,IF(E40=Lookups!$C$6,3,IF(E40=Lookups!$C$7,4,IF(E40=Lookups!$C$8,5,0))))) -> 0 | U40: =IF(I40=Lookups!$B$4,1,IF(I40=Lookups!$B$5,2,IF(I40=Lookups!$B$6,3,IF(I40=Lookups!$B$7,4,IF(I40=Lookups!$B$8,5,0))))) -> 0 | V40: =IF(J40=Lookups!$C$4,1,IF(J40=Lookups!$C$5,2,IF(J40=Lookups!$C$6,3,IF(J40=Lookups!$C$7,4,IF(J40=Lookups!$C$8,5,0))))) -> 0
C41: Volume of traffic in remaining lanes is unacceptably high leading to traffic queues extend through nearby intersections / roundabouts | F41: =IF(P41*Q41=0,$S$15,VLOOKUP(Q41,Lookups!$D$4:$J$8,'Design Phase'!P41+2)) -> Select L & C | K41: =IF(U41*V41=0,$S$15,VLOOKUP(V41,Lookups!$D$4:$J$8,'Design Phase'!U41+2)) -> Select L & C | P41: =IF(D41=Lookups!$B$4,1,IF(D41=Lookups!$B$5,2,IF(D41=Lookups!$B$6,3,IF(D41=Lookups!$B$7,4,IF(D41=Lookups!$B$8,5,0))))) -> 0 | Q41: =IF(E41=Lookups!$C$4,1,IF(E41=Lookups!$C$5,2,IF(E41=Lookups!$C$6,3,IF(E41=Lookups!$C$7,4,IF(E41=Lookups!$C$8,5,0))))) -> 0 | U41: =IF(I41=Lookups!$B$4,1,IF(I41=Lookups!$B$5,2,IF(I41=Lookups!$B$6,3,IF(I41=Lookups!$B$7,4,IF(I41=Lookups!$B$8,5,0))))) -> 0 | V41: =IF(J41=Lookups!$C$4,1,IF(J41=Lookups!$C$5,2,IF(J41=Lookups!$C$6,3,IF(J41=Lookups!$C$7,4,IF(J41=Lookups!$C$8,5,0))))) -> 0
B42: Interference with the operation of permanent traffic signals | C42: Compromised legibility of traffic controls for road users leads to road user confusion leading to increased likelihood of traffic incidents | F42: =IF(P42*Q42=0,$S$15,VLOOKUP(Q42,Lookups!$D$4:$J$8,'Design Phase'!P42+2)) -> Select L & C | K42: =IF(U42*V42=0,$S$15,VLOOKUP(V42,Lookups!$D$4:$J$8,'Design Phase'!U42+2)) -> Select L & C | P42: =IF(D42=Lookups!$B$4,1,IF(D42=Lookups!$B$5,2,IF(D42=Lookups!$B$6,3,IF(D42=Lookups!$B$7,4,IF(D42=Lookups!$B$8,5,0))))) -> 0 | Q42: =IF(E42=Lookups!$C$4,1,IF(E42=Lookups!$C$5,2,IF(E42=Lookups!$C$6,3,IF(E42=Lookups!$C$7,4,IF(E42=Lookups!$C$8,5,0))))) -> 0 | U42: =IF(I42=Lookups!$B$4,1,IF(I42=Lookups!$B$5,2,IF(I42=Lookups!$B$6,3,IF(I42=Lookups!$B$7,4,IF(I42=Lookups!$B$8,5,0))))) -> 0 | V42: =IF(J42=Lookups!$C$4,1,IF(J42=Lookups!$C$5,2,IF(J42=Lookups!$C$6,3,IF(J42=Lookups!$C$7,4,IF(J42=Lookups!$C$8,5,0))))) -> 0
C43: Increased congestion due to works results in queued traffic through signalised intersections leading to unsafe operation of the intersection | F43: =IF(P43*Q43=0,$S$15,VLOOKUP(Q43,Lookups!$D$4:$J$8,'Design Phase'!P43+2)) -> Select L & C | K43: =IF(U43*V43=0,$S$15,VLOOKUP(V43,Lookups!$D$4:$J$8,'Design Phase'!U43+2)) -> Select L & C | P43: =IF(D43=Lookups!$B$4,1,IF(D43=Lookups!$B$5,2,IF(D43=Lookups!$B$6,3,IF(D43=Lookups!$B$7,4,IF(D43=Lookups!$B$8,5,0))))) -> 0 | Q43: =IF(E43=Lookups!$C$4,1,IF(E43=Lookups!$C$5,2,IF(E43=Lookups!$C$6,3,IF(E43=Lookups!$C$7,4,IF(E43=Lookups!$C$8,5,0))))) -> 0 | U43: =IF(I43=Lookups!$B$4,1,IF(I43=Lookups!$B$5,2,IF(I43=Lookups!$B$6,3,IF(I43=Lookups!$B$7,4,IF(I43=Lookups!$B$8,5,0))))) -> 0 | V43: =IF(J43=Lookups!$C$4,1,IF(J43=Lookups!$C$5,2,IF(J43=Lookups!$C$6,3,IF(J43=Lookups!$C$7,4,IF(J43=Lookups!$C$8,5,0))))) -> 0
B44: Closure of turning movements and banning of movements at intersections | C44: Closure of turning movements with no clear alternative leads to road user confusion and increased likelihood of traffic incidents | F44: =IF(P44*Q44=0,$S$15,VLOOKUP(Q44,Lookups!$D$4:$J$8,'Design Phase'!P44+2)) -> Select L & C | K44: =IF(U44*V44=0,$S$15,VLOOKUP(V44,Lookups!$D$4:$J$8,'Design Phase'!U44+2)) -> Select L & C | P44: =IF(D44=Lookups!$B$4,1,IF(D44=Lookups!$B$5,2,IF(D44=Lookups!$B$6,3,IF(D44=Lookups!$B$7,4,IF(D44=Lookups!$B$8,5,0))))) -> 0 | Q44: =IF(E44=Lookups!$C$4,1,IF(E44=Lookups!$C$5,2,IF(E44=Lookups!$C$6,3,IF(E44=Lookups!$C$7,4,IF(E44=Lookups!$C$8,5,0))))) -> 0 | U44: =IF(I44=Lookups!$B$4,1,IF(I44=Lookups!$B$5,2,IF(I44=Lookups!$B$6,3,IF(I44=Lookups!$B$7,4,IF(I44=Lookups!$B$8,5,0))))) -> 0 | V44: =IF(J44=Lookups!$C$4,1,IF(J44=Lookups!$C$5,2,IF(J44=Lookups!$C$6,3,IF(J44=Lookups!$C$7,4,IF(J44=Lookups!$C$8,5,0))))) -> 0
C45: Volume of detoured traffic has unacceptable impact on surrounding areas including - property and business access is compromised - Increased congestion on other parts of the road network leading to compromised safety outcomes | F45: =IF(P45*Q45=0,$S$15,VLOOKUP(Q45,Lookups!$D$4:$J$8,'Design Phase'!P45+2)) -> Select L & C | K45: =IF(U45*V45=0,$S$15,VLOOKUP(V45,Lookups!$D$4:$J$8,'Design Phase'!U45+2)) -> Select L & C | P45: =IF(D45=Lookups!$B$4,1,IF(D45=Lookups!$B$5,2,IF(D45=Lookups!$B$6,3,IF(D45=Lookups!$B$7,4,IF(D45=Lookups!$B$8,5,0))))) -> 0 | Q45: =IF(E45=Lookups!$C$4,1,IF(E45=Lookups!$C$5,2,IF(E45=Lookups!$C$6,3,IF(E45=Lookups!$C$7,4,IF(E45=Lookups!$C$8,5,0))))) -> 0 | U45: =IF(I45=Lookups!$B$4,1,IF(I45=Lookups!$B$5,2,IF(I45=Lookups!$B$6,3,IF(I45=Lookups!$B$7,4,IF(I45=Lookups!$B$8,5,0))))) -> 0 | V45: =IF(J45=Lookups!$C$4,1,IF(J45=Lookups!$C$5,2,IF(J45=Lookups!$C$6,3,IF(J45=Lookups!$C$7,4,IF(J45=Lookups!$C$8,5,0))))) -> 0
B46: Additional design phase items
...

Sheet Implementation Phase
B7: Risk | D7: Initial Risk | G7: Proposed Control Measures | I7: Revised Risk | L7: Selected | M7: Actions | P7: Initial Scores | U7: Initial Scores
B8: Source | C8: Event | D8: Likelihood | E8: Consequence | F8: Rating | G8: Options | H8: Considerations | I8: Likelihood | J8: Consequence | K8: Rating | M8: Who | N8: What | P8: L | Q8: C | U8: L | V8: C
B9: Vulnerable Road Users - pedestrians, cyclists, people with disabilities and wheeled path users | S9: Very High
B10: Unidentified path or unformed pedestrian route impacted by the works | C10: VRUs cross roads in an unsafe manner at unsigned locations | F10: =IF(P10*Q10=0,$S$14,VLOOKUP(Q10,Lookups!$D$4:$J$8,'Implementation Phase'!P10+2)) -> Select L & C | K10: =IF(U10*V10=0,$S$14,VLOOKUP(V10,Lookups!$D$4:$J$8,'Implementation Phase'!U10+2)) -> Select L & C | P10: =IF(D10=Lookups!$B$4,1,IF(D10=Lookups!$B$5,2,IF(D10=Lookups!$B$6,3,IF(D10=Lookups!$B$7,4,IF(D10=Lookups!$B$8,5,0))))) -> 0 | Q10: =IF(E10=Lookups!$C$4,1,IF(E10=Lookups!$C$5,2,IF(E10=Lookups!$C$6,3,IF(E10=Lookups!$C$7,4,IF(E10=Lookups!$C$8,5,0))))) -> 0 | S10: High | U10: =IF(I10=Lookups!$B$4,1,IF(I10=Lookups!$B$5,2,IF(I10=Lookups!$B$6,3,IF(I10=Lookups!$B$7,4,IF(I10=Lookups!$B$8,5,0))))) -> 0 | V10: =IF(J10=Lookups!$C$4,1,IF(J10=Lookups!$C$5,2,IF(J10=Lookups!$C$6,3,IF(J10=Lookups!$C$7,4,IF(J10=Lookups!$C$8,5,0))))) -> 0
